### 프로그램 오류

- 컴파일 에러 : 컴파일 시에 발생하는 에러
- 런타임 에러 : 실행 시에 발생하는 에러
- 논리적 에러 : 실행은 되지만, 의도가 다르게 동작하는 것(창고의 재고가 음수가 된다던가)
- 에러는 메모리부족, 스택오버플로우와 같이 프로그램 코드에 의해서 수습될 수 없는 심각한 오류를 의미하고 예외는 프로그램 코드에 의해서 수습될 수 있는 다소 미약한 오류임

### 예외 클래스의 계층구조

- 발생할 수 있는 오류를 클래스로 정의함(Exception과 Error), 이것도 역시 Object 클래스의 자손임
- 모든 예외의 최고 조상은 Exception 클래스임
- 여기서 더 나눈다면 Exception클래스와 그 자손, RuntimeException클래스와 그 자손들로 나눌 수 있음
- RuntimeException클래스들은 주로 프로그래머의 실수에 의해서 발생될 수 있는 예외들로 자바의 프로그래밍 요소들과 관계가 깊음(배열의 범위를 벗어난다던가, null인 참조변수의 멤버를 호출하려 했다던가, 형변환을 잘못했다던가, 정수를 0으로 나누려고 했다던가)
- Exception클래스들은 주로 외부의 영향으로 발생할 수 있는 것들로서, 프로그램의 사용자들의 동작에 의해서 발생하는 경우가 많음(존재하지 않는 파일의 이름을 입력했다던가, 실수로 클래스의 이름을 잘못 적었다던가, 또는 입력한 데이터 형식이 잘못된 경우)

### 예외처리하기 - try-catch 문

- 에러는 어쩔 수 없지만 예외는 이에 대한 처리를 미리 해주어야 함
- 예외처리란 프로그램 실행 시 발생할 수 있는 예기치 못한 예외의 발생에 대비한 코드를 작성하는 것이며, 예외처리의 목적은 예외의 발생으로 인한 실행 중인 프로그램의 갑작스런 비정상 종료를 막고, 정상적인 실행상태를 유지할 수 있도록 하는것임
- 발생한 예외를 처리하지 못하면 프로그램은 비정상적으로 종료되며, 처리되지 못한 예외는 JVM의 예외처리기가 받아서 예외의 원인을 화면에 출력함

```java
try {
			// 예외가 발생할 가능성이 있는 문장들을 넣음
} catch (Exception1 e1) {
			// Exception1이 발생했을 경우, 이를 처리하기 위한 문장을 적음.
} catch (Exception2 e2) {
			// Exception2이 발생했을 경우, 이를 처리하기 위한 문장을 적음.
} catch (Exception3 e3) {
			// Exception3이 발생했을 경우, 이를 처리하기 위한 문장을 적음.
}
```

- 하나의 try블럭 다음에는 여러 종류의 예외를 처리할 수 있도록 하나 이상의 catch블럭이 올 수 있으며, 이 중 발생한 예외의 종류와 일치하는 단 한 개의 catch블럭만 수행됨
- 발생한 예외의 종류와 일치하는 catch블럭이 없으면 예외는 처리되지 않음
- 하나의 메서드 내에 여러 개의 try-catch문이 사용될 수 있으며, try블럭 또는 catch블럭에 또 다른 try-catch문이 포함될 수 있음
- catch 블럭 내에 또 하나의 try-catch문이 포함된 경우, 같은 이름의 참조변수를 사용해서는 안됨, 서로 다른 이름을 써야함
- 실제 적용 예시

```java
class ExceptionEx3 {
	 public static void main(String args[]) {
			 int number = 100;
			 int result = 0;

			 for(int i=0; i < 10; i++) {
					 try {
							 result = number / (int)(Math.random() * 10);
							 System.out.println(result);
					 } catch (ArithmeticException e) {
							 System.out.println("0");
					 } // try-catch 끝
			 } // for문 끝
		}
}
```

- 위처럼 해당 예외가 발생시 catch블럭 내의 문장들을 실행한 다음 for문을 다시 반복 수행함, 즉 예외가 발생해서 비정상적 종료가 되지 않음

### try-catch문에서의 흐름

- 예외가 발생한 경우와 발생하지 않았을 때의 흐름이 달라지는데
- try블럭 내에서 예외가 발생한 경우
    - 발생한 예외와 일치하는 catch 블럭이 있는지 확인함
    - 일치하는 catch블럭을 찾게 되면, 그 catch블럭 내의 문장들을 수행하고 전체 try-catch문을 빠져나가서 그 다음 문장을 계속해서 수행함, 만일 일치하는 catch블럭을 찾지 못하면, 예외는 처리되지 못함
- try블럭 내에서 예외가 발생하지 않은 경우
    - catch블럭을 거치지 않고 전체 try-catch문을 빠져나가서 수행을 계속함
- try블럭에서 예외가 발생하면, 예외가 발생한 위치 이후에 있는 try블럭의 문장들은 수행되지 않으므로, try블럭에 포함시킬 코드의 범위를 잘 선택해야함

### 예외의 발생과 catch블럭

- catch 블럭은 괄호()와 블럭{} 두 부분으로 나뉘어지는데 괄호()내에는 처리하고자 하는 예외와 같은 타입의 참조변수 하나를 선언해야함

```java
class ExceptionEx7 {
	 public static void main(String args[]) {
			 System.out.println(1);
			 System.out.println(2);
			 try {
					 System.out.println(3);
					 System.out.println(0/0);
					 System.out.printn(4); // 실행되지 않음
			 } catch (ArithmeticException ae)   {
					 if (ae instanceof ArithmeticException)
							 System.out.println("true");
					 System.out.println("ArithmeticException");
			 } catch (Exception e) {
					 System.out.println("Exception");
			 } // try-catch의 끝
			 System.out.println(6);
	 } // main 메서드 끝
}
```

- 위의 예시는 첫 번째 검사에서 일치하는 catch 블럭을 찾았으므로 해당 내용만 출력하고 두 번째 catch 블럭은 검사하지 않음

### printStackTrace()와 getMessage()

- 예외에 대한 정보를 얻을 수 있음
- printStackTrace()
    - 예외발생 당시의 호출스택(Call Stack)에 있었던 메서드의 정보와 예외 메시지를 화면에 출력함
- getMessage()
    - 발생한 예외클래스의 인스턴스에 저장된 메시지를 얻을 수 있음
- 멀티 catch블럭
- '|' 기호를 활용해서 하나의 catch 블럭으로 합칠 수 있게 됨

```java
try {
		...
} catch (ExceptionA | ExceptionB e) {
		e.printStackTrace();
}
```

### 예외 발생시키기

- throw를 사용해서 고의로 예외를 발생시킬 수 있음

```java
class ExceptionEx9 {
	 public static void main(String args[]) {
			 try {
					 Exception e = new Exception("고의로 발생시켰음.");
					 throw e; // 예외를 발생시킴
			//   throw new Exception("고의로 발생시켰음."); // 한 줄로 쓸 수 있음
		} catch (Exception e)     {
				System.out.println("에러 메시지 : " + e.getMessage());
				 e.printStackTrace();
		}
		System.out.println("프로그램이 정상 종료되었음.");
	 }
}
```

- 여기서 RuntimeException클래스와 그 자손에 해당하는 예외는 프로그래머에 의해 실수로 발생하는 것들이기 때문에 에외처리를 강제하지 않음
- 컴파일러가 예외처리를 확인하지 않는 RuntimeException클래스들은 unchecked예외라고 부르고, 예외처리를 확인하는 Exception클래스들은 checked예외라고 함

### 메서드에 예외 선언하기

- 메서드의 선언부에 키워드 throws를 사용해서 메서드 내에서 발생할 수 있는 예외를 적어주기만 하면 됨, 예외가 여러 개일 경우에는 쉼표로 구분함
- 예시를 통해서 본다면

```java
class ExceptionEx12 {
	 public static void main(String[] args) throws Exception {
			method1(); // 같은 클래스내의 static 멤버이므로 객체생성없이 직접 호출가능
	 } // main메서드의 끝
	
	 static void method1() throws Exception {
		  method2();
	 } // method1의 끝

	 static void method2() throws Exception {
		 throw new Exception();
	 } // method2의 끝
}
```

- 예외를 메서드의 throws에 명시하는 것은 예외를 처리하는 것이 아니라, 자신(예외가 발생할 가능성이 있는 메서드)을 호출한 메서드에게 예외를 전달하여 예외처리를 떠맡기는 것임
- 즉 위의 예시를 보면 예외가 발생했을 때 모두 3개의 메서드(main, method1, method2)가 호출스택에 있었으며, 예외가 발생한 곳은 제일 윗줄에 있는 method2()라는 것과 main메서드가 method1()을, 그리고 method1()은 method2()를 호출했다는 것을 알 수 있음
- 이는 예외를 단순히 전달만 해준 것이기 때문에 결국 어느 한 곳에서는 반드시 try-catch문으로 예외처리를 해줘야함

### finally 블럭

- 예외의 발생여부에 상관없이 실행되어야 할 코드를 포함싴리 목적으로 사용됨
- 예외가 발생한 경우 try - catch - finally 순, 예외가 발생하지 않은 경우에는 try → finally순으로 구성됨

### 자동 자원 반환

- try - with - resources문
- 입출력에 사용되는 클래스 중에서는 사용한 후에 꼭 닫아 줘야 하는 것들이 있음, 그래야 사용했던 자원(resources)이 반환되기 때문임

### 사용자정의 예외 만들기

- 필요에 따라서 새로운 예외 클래스를 정의하여 사용할 수 있음, 필요에 따라서 알맞은 예외 클래스를 선택할 수 있음

### 예외 되던지기

- 예외를 처리한 후 인위적으로 다시 발생시키는 방법
- 예외가 발생할 가능성이 있는 메서드에서 try - catch문을 사용해서 예외를 처리해주고 catch문에서 필요한 작업을 행한 후에 throw문을 사용해서 예외를 다시 발생시킴

### 연결된 예외

- 한 예외가 다른 예외를 발생시킬 수도 있음

```java
Throwable initCause(Thorwable cause) // 지정한 예외를 원인 예외로 등록
Throwable getCause() // 원인 예외를 반환
```